Traceback (most recent call last):
  File "/home/ibarra/anaconda3/lib/python3.13/site-packages/nbclient/client.py", line 782, in _async_poll_for_reply
    msg = await ensure_async(self.kc.shell_channel.get_msg(timeout=new_timeout))
          ^^^^^^^^^^^^^^^^^^^^^^^^^^^^^^^^^^^^^^^^^^^^^^^^^^^^^^^^^^^^^^^^^^^^^^
  File "/home/ibarra/anaconda3/lib/python3.13/site-packages/jupyter_core/utils/__init__.py", line 198, in ensure_async
    result = await obj
             ^^^^^^^^^
  File "/home/ibarra/anaconda3/lib/python3.13/site-packages/jupyter_client/channels.py", line 313, in get_msg
    raise Empty
_queue.Empty

During handling of the above exception, another exception occurred:

Traceback (most recent call last):
  File "/home/ibarra/anaconda3/lib/python3.13/site-packages/jupyter_cache/executors/utils.py", line 58, in single_nb_execution
    executenb(
    ~~~~~~~~~^
        nb,
        ^^^
    ...<4 lines>...
        **kwargs,
        ^^^^^^^^^
    )
    ^
  File "/home/ibarra/anaconda3/lib/python3.13/site-packages/nbclient/client.py", line 1319, in execute
    return NotebookClient(nb=nb, resources=resources, km=km, **kwargs).execute()
           ~~~~~~~~~~~~~~~~~~~~~~~~~~~~~~~~~~~~~~~~~~~~~~~~~~~~~~~~~~~~~~~~~~~^^
  File "/home/ibarra/anaconda3/lib/python3.13/site-packages/jupyter_core/utils/__init__.py", line 165, in wrapped
    return loop.run_until_complete(inner)
           ~~~~~~~~~~~~~~~~~~~~~~~^^^^^^^
  File "/home/ibarra/anaconda3/lib/python3.13/asyncio/base_events.py", line 725, in run_until_complete
    return future.result()
           ~~~~~~~~~~~~~^^
  File "/home/ibarra/anaconda3/lib/python3.13/site-packages/nbclient/client.py", line 709, in async_execute
    await self.async_execute_cell(
        cell, index, execution_count=self.code_cells_executed + 1
    )
  File "/home/ibarra/anaconda3/lib/python3.13/site-packages/nbclient/client.py", line 1005, in async_execute_cell
    exec_reply = await self.task_poll_for_reply
                 ^^^^^^^^^^^^^^^^^^^^^^^^^^^^^^
  File "/home/ibarra/anaconda3/lib/python3.13/site-packages/nbclient/client.py", line 806, in _async_poll_for_reply
    error_on_timeout_execute_reply = await self._async_handle_timeout(timeout, cell)
                                     ^^^^^^^^^^^^^^^^^^^^^^^^^^^^^^^^^^^^^^^^^^^^^^^
  File "/home/ibarra/anaconda3/lib/python3.13/site-packages/nbclient/client.py", line 856, in _async_handle_timeout
    raise CellTimeoutError.error_from_timeout_and_cell(
        "Cell execution timed out", timeout, cell
    )
nbclient.exceptions.CellTimeoutError: A cell timed out while it was being executed, after 30 seconds.
The message was: Cell execution timed out.
Here is a preview of the cell contents:
-------------------
['# --- 3. Random Forest ---', 'rf = RandomForestRegressor(n_estimators=100, max_depth=20, random_state=42, n_jobs=-1)', 'start = time.time()', 'rf.fit(features_train_ohe, target_train)', 'train_time = time.time() - start']
...
["results['RandomForest'] = {", "    'rmse': rmse(target_test, preds_rf),", "    'train_time': train_time,", "    'predict_time': predict_time", '}']
-------------------

